[2022-11-12T13:44:49.957+0000] {processor.py:154} INFO - Started process (PID=420) to work on /opt/airflow/dags/etl_testDef.py
[2022-11-12T13:44:49.960+0000] {processor.py:756} INFO - Processing file /opt/airflow/dags/etl_testDef.py for tasks to queue
[2022-11-12T13:44:49.962+0000] {logging_mixin.py:120} INFO - [2022-11-12T13:44:49.962+0000] {dagbag.py:537} INFO - Filling up the DagBag from /opt/airflow/dags/etl_testDef.py
[2022-11-12T13:44:50.490+0000] {logging_mixin.py:120} INFO - Grupo 99 ....>> runing ETL
[2022-11-12T13:44:50.491+0000] {logging_mixin.py:120} INFO - [E]XTRACT DATA
[2022-11-12T13:44:50.492+0000] {logging_mixin.py:120} INFO -   begin Extract >> PAYMENTS
[2022-11-12T13:44:50.494+0000] {logging_mixin.py:120} INFO - Error mientras extracción de datos: [Errno 2] No such file or directory: '/Users/napo/Documents/proyecto/Big Data/BigData/data/payments'
[2022-11-12T13:44:50.495+0000] {logging_mixin.py:120} INFO -   >>end Extract PAYMENTS..
[2022-11-12T13:44:50.496+0000] {logging_mixin.py:120} INFO -   begin Extract >> CHARGEBACKS
[2022-11-12T13:44:50.501+0000] {logging_mixin.py:120} INFO - Error mientras extracción de datos: [Errno 2] No such file or directory: '/Users/napo/Documents/proyecto/Big Data/BigData/data/chargebacks'
[2022-11-12T13:44:50.502+0000] {logging_mixin.py:120} INFO -   >>end Extract CHARGEBACKS..
[2022-11-12T13:44:50.503+0000] {logging_mixin.py:120} INFO - [end] - EXTRACT-DATA
[2022-11-12T13:44:50.506+0000] {logging_mixin.py:120} INFO - >>El tiempo total de ejecucion del script [extract] es:     0.015750408172607422 Segundos
[2022-11-12T13:44:50.510+0000] {logging_mixin.py:120} INFO - [T]RANSFORM DATA
[2022-11-12T13:44:50.513+0000] {logging_mixin.py:120} INFO - Error mientras extracción de datos: (psycopg2.OperationalError) connection to server at "localhost" (127.0.0.1), port 5438 failed: Connection refused
	Is the server running on that host and accepting TCP/IP connections?
connection to server at "localhost" (::1), port 5438 failed: Cannot assign requested address
	Is the server running on that host and accepting TCP/IP connections?

(Background on this error at: https://sqlalche.me/e/14/e3q8)
[2022-11-12T13:44:50.518+0000] {logging_mixin.py:120} INFO - [L]OAD DATA 
[2022-11-12T13:44:50.523+0000] {logging_mixin.py:120} INFO - Error mientras extracción de datos: (psycopg2.OperationalError) connection to server at "localhost" (127.0.0.1), port 5438 failed: Connection refused
	Is the server running on that host and accepting TCP/IP connections?
connection to server at "localhost" (::1), port 5438 failed: Cannot assign requested address
	Is the server running on that host and accepting TCP/IP connections?

(Background on this error at: https://sqlalche.me/e/14/e3q8)
[2022-11-12T13:44:50.548+0000] {logging_mixin.py:120} INFO - [2022-11-12T13:44:50.542+0000] {dagbag.py:342} ERROR - Failed to import: /opt/airflow/dags/etl_testDef.py
Traceback (most recent call last):
  File "/home/airflow/.local/lib/python3.7/site-packages/airflow/models/dagbag.py", line 338, in parse
    loader.exec_module(new_module)
  File "<frozen importlib._bootstrap_external>", line 728, in exec_module
  File "<frozen importlib._bootstrap>", line 219, in _call_with_frames_removed
  File "/opt/airflow/dags/etl_testDef.py", line 37, in <module>
    python_callable=extract
  File "/home/airflow/.local/lib/python3.7/site-packages/airflow/models/baseoperator.py", line 408, in apply_defaults
    result = func(self, **kwargs, default_args=default_args)
  File "/home/airflow/.local/lib/python3.7/site-packages/airflow/operators/python.py", line 162, in __init__
    raise AirflowException('`python_callable` param must be callable')
airflow.exceptions.AirflowException: `python_callable` param must be callable
[2022-11-12T13:44:50.552+0000] {processor.py:768} WARNING - No viable dags retrieved from /opt/airflow/dags/etl_testDef.py
[2022-11-12T13:44:50.706+0000] {processor.py:176} INFO - Processing /opt/airflow/dags/etl_testDef.py took 0.760 seconds
[2022-11-12T13:45:21.331+0000] {processor.py:154} INFO - Started process (PID=434) to work on /opt/airflow/dags/etl_testDef.py
[2022-11-12T13:45:21.335+0000] {processor.py:756} INFO - Processing file /opt/airflow/dags/etl_testDef.py for tasks to queue
[2022-11-12T13:45:21.337+0000] {logging_mixin.py:120} INFO - [2022-11-12T13:45:21.337+0000] {dagbag.py:537} INFO - Filling up the DagBag from /opt/airflow/dags/etl_testDef.py
[2022-11-12T13:45:21.676+0000] {logging_mixin.py:120} INFO - Grupo 99 ....>> runing ETL
[2022-11-12T13:45:21.677+0000] {logging_mixin.py:120} INFO - [E]XTRACT DATA
[2022-11-12T13:45:21.679+0000] {logging_mixin.py:120} INFO -   begin Extract >> PAYMENTS
[2022-11-12T13:45:21.680+0000] {logging_mixin.py:120} INFO - Error mientras extracción de datos: [Errno 2] No such file or directory: '/Users/napo/Documents/proyecto/Big Data/BigData/data/payments'
[2022-11-12T13:45:21.682+0000] {logging_mixin.py:120} INFO -   >>end Extract PAYMENTS..
[2022-11-12T13:45:21.683+0000] {logging_mixin.py:120} INFO -   begin Extract >> CHARGEBACKS
[2022-11-12T13:45:21.684+0000] {logging_mixin.py:120} INFO - Error mientras extracción de datos: [Errno 2] No such file or directory: '/Users/napo/Documents/proyecto/Big Data/BigData/data/chargebacks'
[2022-11-12T13:45:21.685+0000] {logging_mixin.py:120} INFO -   >>end Extract CHARGEBACKS..
[2022-11-12T13:45:21.687+0000] {logging_mixin.py:120} INFO - [end] - EXTRACT-DATA
[2022-11-12T13:45:21.688+0000] {logging_mixin.py:120} INFO - >>El tiempo total de ejecucion del script [extract] es:     0.012521982192993164 Segundos
[2022-11-12T13:45:21.692+0000] {logging_mixin.py:120} INFO - [T]RANSFORM DATA
[2022-11-12T13:45:21.698+0000] {logging_mixin.py:120} INFO - Error mientras extracción de datos: (psycopg2.OperationalError) connection to server at "localhost" (127.0.0.1), port 5438 failed: Connection refused
	Is the server running on that host and accepting TCP/IP connections?
connection to server at "localhost" (::1), port 5438 failed: Cannot assign requested address
	Is the server running on that host and accepting TCP/IP connections?

(Background on this error at: https://sqlalche.me/e/14/e3q8)
[2022-11-12T13:45:21.702+0000] {logging_mixin.py:120} INFO - [L]OAD DATA 
[2022-11-12T13:45:21.704+0000] {logging_mixin.py:120} INFO - Error mientras extracción de datos: (psycopg2.OperationalError) connection to server at "localhost" (127.0.0.1), port 5438 failed: Connection refused
	Is the server running on that host and accepting TCP/IP connections?
connection to server at "localhost" (::1), port 5438 failed: Cannot assign requested address
	Is the server running on that host and accepting TCP/IP connections?

(Background on this error at: https://sqlalche.me/e/14/e3q8)
[2022-11-12T13:45:21.715+0000] {logging_mixin.py:120} INFO - [2022-11-12T13:45:21.712+0000] {dagbag.py:342} ERROR - Failed to import: /opt/airflow/dags/etl_testDef.py
Traceback (most recent call last):
  File "/home/airflow/.local/lib/python3.7/site-packages/airflow/models/dagbag.py", line 338, in parse
    loader.exec_module(new_module)
  File "<frozen importlib._bootstrap_external>", line 728, in exec_module
  File "<frozen importlib._bootstrap>", line 219, in _call_with_frames_removed
  File "/opt/airflow/dags/etl_testDef.py", line 37, in <module>
    python_callable=extract
  File "/home/airflow/.local/lib/python3.7/site-packages/airflow/models/baseoperator.py", line 408, in apply_defaults
    result = func(self, **kwargs, default_args=default_args)
  File "/home/airflow/.local/lib/python3.7/site-packages/airflow/operators/python.py", line 162, in __init__
    raise AirflowException('`python_callable` param must be callable')
airflow.exceptions.AirflowException: `python_callable` param must be callable
[2022-11-12T13:45:21.717+0000] {processor.py:768} WARNING - No viable dags retrieved from /opt/airflow/dags/etl_testDef.py
[2022-11-12T13:45:21.749+0000] {processor.py:176} INFO - Processing /opt/airflow/dags/etl_testDef.py took 0.423 seconds
[2022-11-12T13:45:52.202+0000] {processor.py:154} INFO - Started process (PID=445) to work on /opt/airflow/dags/etl_testDef.py
[2022-11-12T13:45:52.207+0000] {processor.py:756} INFO - Processing file /opt/airflow/dags/etl_testDef.py for tasks to queue
[2022-11-12T13:45:52.211+0000] {logging_mixin.py:120} INFO - [2022-11-12T13:45:52.211+0000] {dagbag.py:537} INFO - Filling up the DagBag from /opt/airflow/dags/etl_testDef.py
[2022-11-12T13:45:52.848+0000] {logging_mixin.py:120} INFO - Grupo 99 ....>> runing ETL
[2022-11-12T13:45:52.853+0000] {logging_mixin.py:120} INFO - [E]XTRACT DATA
[2022-11-12T13:45:52.854+0000] {logging_mixin.py:120} INFO -   begin Extract >> PAYMENTS
[2022-11-12T13:45:52.855+0000] {logging_mixin.py:120} INFO - Error mientras extracción de datos: [Errno 2] No such file or directory: '/Users/napo/Documents/proyecto/Big Data/BigData/data/payments'
[2022-11-12T13:45:52.856+0000] {logging_mixin.py:120} INFO -   >>end Extract PAYMENTS..
[2022-11-12T13:45:52.857+0000] {logging_mixin.py:120} INFO -   begin Extract >> CHARGEBACKS
[2022-11-12T13:45:52.858+0000] {logging_mixin.py:120} INFO - Error mientras extracción de datos: [Errno 2] No such file or directory: '/Users/napo/Documents/proyecto/Big Data/BigData/data/chargebacks'
[2022-11-12T13:45:52.859+0000] {logging_mixin.py:120} INFO -   >>end Extract CHARGEBACKS..
[2022-11-12T13:45:52.860+0000] {logging_mixin.py:120} INFO - [end] - EXTRACT-DATA
[2022-11-12T13:45:52.861+0000] {logging_mixin.py:120} INFO - >>El tiempo total de ejecucion del script [extract] es:     0.013520240783691406 Segundos
[2022-11-12T13:45:52.863+0000] {logging_mixin.py:120} INFO - [T]RANSFORM DATA
[2022-11-12T13:45:52.866+0000] {logging_mixin.py:120} INFO - Error mientras extracción de datos: (psycopg2.OperationalError) connection to server at "localhost" (127.0.0.1), port 5438 failed: Connection refused
	Is the server running on that host and accepting TCP/IP connections?
connection to server at "localhost" (::1), port 5438 failed: Cannot assign requested address
	Is the server running on that host and accepting TCP/IP connections?

(Background on this error at: https://sqlalche.me/e/14/e3q8)
[2022-11-12T13:45:52.872+0000] {logging_mixin.py:120} INFO - [L]OAD DATA 
[2022-11-12T13:45:52.875+0000] {logging_mixin.py:120} INFO - Error mientras extracción de datos: (psycopg2.OperationalError) connection to server at "localhost" (127.0.0.1), port 5438 failed: Connection refused
	Is the server running on that host and accepting TCP/IP connections?
connection to server at "localhost" (::1), port 5438 failed: Cannot assign requested address
	Is the server running on that host and accepting TCP/IP connections?

(Background on this error at: https://sqlalche.me/e/14/e3q8)
[2022-11-12T13:45:52.890+0000] {logging_mixin.py:120} INFO - [2022-11-12T13:45:52.886+0000] {dagbag.py:342} ERROR - Failed to import: /opt/airflow/dags/etl_testDef.py
Traceback (most recent call last):
  File "/home/airflow/.local/lib/python3.7/site-packages/airflow/models/dagbag.py", line 338, in parse
    loader.exec_module(new_module)
  File "<frozen importlib._bootstrap_external>", line 728, in exec_module
  File "<frozen importlib._bootstrap>", line 219, in _call_with_frames_removed
  File "/opt/airflow/dags/etl_testDef.py", line 37, in <module>
    python_callable=extract
  File "/home/airflow/.local/lib/python3.7/site-packages/airflow/models/baseoperator.py", line 408, in apply_defaults
    result = func(self, **kwargs, default_args=default_args)
  File "/home/airflow/.local/lib/python3.7/site-packages/airflow/operators/python.py", line 162, in __init__
    raise AirflowException('`python_callable` param must be callable')
airflow.exceptions.AirflowException: `python_callable` param must be callable
[2022-11-12T13:45:52.892+0000] {processor.py:768} WARNING - No viable dags retrieved from /opt/airflow/dags/etl_testDef.py
[2022-11-12T13:45:52.923+0000] {processor.py:176} INFO - Processing /opt/airflow/dags/etl_testDef.py took 0.728 seconds
[2022-11-12T13:46:23.936+0000] {processor.py:154} INFO - Started process (PID=456) to work on /opt/airflow/dags/etl_testDef.py
[2022-11-12T13:46:23.941+0000] {processor.py:756} INFO - Processing file /opt/airflow/dags/etl_testDef.py for tasks to queue
[2022-11-12T13:46:23.946+0000] {logging_mixin.py:120} INFO - [2022-11-12T13:46:23.945+0000] {dagbag.py:537} INFO - Filling up the DagBag from /opt/airflow/dags/etl_testDef.py
[2022-11-12T13:46:24.650+0000] {logging_mixin.py:120} INFO - Grupo 99 ....>> runing ETL
[2022-11-12T13:46:24.655+0000] {logging_mixin.py:120} INFO - [E]XTRACT DATA
[2022-11-12T13:46:24.659+0000] {logging_mixin.py:120} INFO -   begin Extract >> PAYMENTS
[2022-11-12T13:46:24.661+0000] {logging_mixin.py:120} INFO - Error mientras extracción de datos: [Errno 2] No such file or directory: '/Users/napo/Documents/proyecto/Big Data/BigData/data/payments'
[2022-11-12T13:46:24.662+0000] {logging_mixin.py:120} INFO -   >>end Extract PAYMENTS..
[2022-11-12T13:46:24.664+0000] {logging_mixin.py:120} INFO -   begin Extract >> CHARGEBACKS
[2022-11-12T13:46:24.666+0000] {logging_mixin.py:120} INFO - Error mientras extracción de datos: [Errno 2] No such file or directory: '/Users/napo/Documents/proyecto/Big Data/BigData/data/chargebacks'
[2022-11-12T13:46:24.667+0000] {logging_mixin.py:120} INFO -   >>end Extract CHARGEBACKS..
[2022-11-12T13:46:24.672+0000] {logging_mixin.py:120} INFO - [end] - EXTRACT-DATA
[2022-11-12T13:46:24.677+0000] {logging_mixin.py:120} INFO - >>El tiempo total de ejecucion del script [extract] es:     0.02649235725402832 Segundos
[2022-11-12T13:46:24.693+0000] {logging_mixin.py:120} INFO - [T]RANSFORM DATA
[2022-11-12T13:46:24.698+0000] {logging_mixin.py:120} INFO - Error mientras extracción de datos: (psycopg2.OperationalError) connection to server at "localhost" (127.0.0.1), port 5438 failed: Connection refused
	Is the server running on that host and accepting TCP/IP connections?
connection to server at "localhost" (::1), port 5438 failed: Cannot assign requested address
	Is the server running on that host and accepting TCP/IP connections?

(Background on this error at: https://sqlalche.me/e/14/e3q8)
[2022-11-12T13:46:24.716+0000] {logging_mixin.py:120} INFO - [L]OAD DATA 
[2022-11-12T13:46:24.727+0000] {logging_mixin.py:120} INFO - Error mientras extracción de datos: (psycopg2.OperationalError) connection to server at "localhost" (127.0.0.1), port 5438 failed: Connection refused
	Is the server running on that host and accepting TCP/IP connections?
connection to server at "localhost" (::1), port 5438 failed: Cannot assign requested address
	Is the server running on that host and accepting TCP/IP connections?

(Background on this error at: https://sqlalche.me/e/14/e3q8)
[2022-11-12T13:46:24.745+0000] {logging_mixin.py:120} INFO - [2022-11-12T13:46:24.737+0000] {dagbag.py:342} ERROR - Failed to import: /opt/airflow/dags/etl_testDef.py
Traceback (most recent call last):
  File "/home/airflow/.local/lib/python3.7/site-packages/airflow/models/dagbag.py", line 338, in parse
    loader.exec_module(new_module)
  File "<frozen importlib._bootstrap_external>", line 728, in exec_module
  File "<frozen importlib._bootstrap>", line 219, in _call_with_frames_removed
  File "/opt/airflow/dags/etl_testDef.py", line 37, in <module>
    python_callable=extract
  File "/home/airflow/.local/lib/python3.7/site-packages/airflow/models/baseoperator.py", line 408, in apply_defaults
    result = func(self, **kwargs, default_args=default_args)
  File "/home/airflow/.local/lib/python3.7/site-packages/airflow/operators/python.py", line 162, in __init__
    raise AirflowException('`python_callable` param must be callable')
airflow.exceptions.AirflowException: `python_callable` param must be callable
[2022-11-12T13:46:24.747+0000] {processor.py:768} WARNING - No viable dags retrieved from /opt/airflow/dags/etl_testDef.py
[2022-11-12T13:46:24.811+0000] {processor.py:176} INFO - Processing /opt/airflow/dags/etl_testDef.py took 0.883 seconds
[2022-11-12T13:46:54.993+0000] {processor.py:154} INFO - Started process (PID=467) to work on /opt/airflow/dags/etl_testDef.py
[2022-11-12T13:46:54.997+0000] {processor.py:756} INFO - Processing file /opt/airflow/dags/etl_testDef.py for tasks to queue
[2022-11-12T13:46:54.999+0000] {logging_mixin.py:120} INFO - [2022-11-12T13:46:54.998+0000] {dagbag.py:537} INFO - Filling up the DagBag from /opt/airflow/dags/etl_testDef.py
[2022-11-12T13:46:55.351+0000] {logging_mixin.py:120} INFO - Grupo 99 ....>> runing ETL
[2022-11-12T13:46:55.352+0000] {logging_mixin.py:120} INFO - [E]XTRACT DATA
[2022-11-12T13:46:55.354+0000] {logging_mixin.py:120} INFO -   begin Extract >> PAYMENTS
[2022-11-12T13:46:55.355+0000] {logging_mixin.py:120} INFO - Error mientras extracción de datos: [Errno 2] No such file or directory: '/Users/napo/Documents/proyecto/Big Data/BigData/data/payments'
[2022-11-12T13:46:55.356+0000] {logging_mixin.py:120} INFO -   >>end Extract PAYMENTS..
[2022-11-12T13:46:55.357+0000] {logging_mixin.py:120} INFO -   begin Extract >> CHARGEBACKS
[2022-11-12T13:46:55.358+0000] {logging_mixin.py:120} INFO - Error mientras extracción de datos: [Errno 2] No such file or directory: '/Users/napo/Documents/proyecto/Big Data/BigData/data/chargebacks'
[2022-11-12T13:46:55.359+0000] {logging_mixin.py:120} INFO -   >>end Extract CHARGEBACKS..
[2022-11-12T13:46:55.360+0000] {logging_mixin.py:120} INFO - [end] - EXTRACT-DATA
[2022-11-12T13:46:55.361+0000] {logging_mixin.py:120} INFO - >>El tiempo total de ejecucion del script [extract] es:     0.0100555419921875 Segundos
[2022-11-12T13:46:55.363+0000] {logging_mixin.py:120} INFO - [T]RANSFORM DATA
[2022-11-12T13:46:55.368+0000] {logging_mixin.py:120} INFO - Error mientras extracción de datos: (psycopg2.OperationalError) connection to server at "localhost" (127.0.0.1), port 5438 failed: Connection refused
	Is the server running on that host and accepting TCP/IP connections?
connection to server at "localhost" (::1), port 5438 failed: Cannot assign requested address
	Is the server running on that host and accepting TCP/IP connections?

(Background on this error at: https://sqlalche.me/e/14/e3q8)
[2022-11-12T13:46:55.371+0000] {logging_mixin.py:120} INFO - [L]OAD DATA 
[2022-11-12T13:46:55.375+0000] {logging_mixin.py:120} INFO - Error mientras extracción de datos: (psycopg2.OperationalError) connection to server at "localhost" (127.0.0.1), port 5438 failed: Connection refused
	Is the server running on that host and accepting TCP/IP connections?
connection to server at "localhost" (::1), port 5438 failed: Cannot assign requested address
	Is the server running on that host and accepting TCP/IP connections?

(Background on this error at: https://sqlalche.me/e/14/e3q8)
[2022-11-12T13:46:55.386+0000] {logging_mixin.py:120} INFO - [2022-11-12T13:46:55.382+0000] {dagbag.py:342} ERROR - Failed to import: /opt/airflow/dags/etl_testDef.py
Traceback (most recent call last):
  File "/home/airflow/.local/lib/python3.7/site-packages/airflow/models/dagbag.py", line 338, in parse
    loader.exec_module(new_module)
  File "<frozen importlib._bootstrap_external>", line 728, in exec_module
  File "<frozen importlib._bootstrap>", line 219, in _call_with_frames_removed
  File "/opt/airflow/dags/etl_testDef.py", line 37, in <module>
    python_callable=extract
  File "/home/airflow/.local/lib/python3.7/site-packages/airflow/models/baseoperator.py", line 408, in apply_defaults
    result = func(self, **kwargs, default_args=default_args)
  File "/home/airflow/.local/lib/python3.7/site-packages/airflow/operators/python.py", line 162, in __init__
    raise AirflowException('`python_callable` param must be callable')
airflow.exceptions.AirflowException: `python_callable` param must be callable
[2022-11-12T13:46:55.388+0000] {processor.py:768} WARNING - No viable dags retrieved from /opt/airflow/dags/etl_testDef.py
[2022-11-12T13:46:55.421+0000] {processor.py:176} INFO - Processing /opt/airflow/dags/etl_testDef.py took 0.433 seconds
[2022-11-12T13:47:25.846+0000] {processor.py:154} INFO - Started process (PID=478) to work on /opt/airflow/dags/etl_testDef.py
[2022-11-12T13:47:25.849+0000] {processor.py:756} INFO - Processing file /opt/airflow/dags/etl_testDef.py for tasks to queue
[2022-11-12T13:47:25.851+0000] {logging_mixin.py:120} INFO - [2022-11-12T13:47:25.851+0000] {dagbag.py:537} INFO - Filling up the DagBag from /opt/airflow/dags/etl_testDef.py
[2022-11-12T13:47:26.442+0000] {logging_mixin.py:120} INFO - Grupo 99 ....>> runing ETL
[2022-11-12T13:47:26.444+0000] {logging_mixin.py:120} INFO - [E]XTRACT DATA
[2022-11-12T13:47:26.445+0000] {logging_mixin.py:120} INFO -   begin Extract >> PAYMENTS
[2022-11-12T13:47:26.446+0000] {logging_mixin.py:120} INFO - Error mientras extracción de datos: [Errno 2] No such file or directory: '/Users/napo/Documents/proyecto/Big Data/BigData/data/payments'
[2022-11-12T13:47:26.447+0000] {logging_mixin.py:120} INFO -   >>end Extract PAYMENTS..
[2022-11-12T13:47:26.448+0000] {logging_mixin.py:120} INFO -   begin Extract >> CHARGEBACKS
[2022-11-12T13:47:26.450+0000] {logging_mixin.py:120} INFO - Error mientras extracción de datos: [Errno 2] No such file or directory: '/Users/napo/Documents/proyecto/Big Data/BigData/data/chargebacks'
[2022-11-12T13:47:26.451+0000] {logging_mixin.py:120} INFO -   >>end Extract CHARGEBACKS..
[2022-11-12T13:47:26.452+0000] {logging_mixin.py:120} INFO - [end] - EXTRACT-DATA
[2022-11-12T13:47:26.453+0000] {logging_mixin.py:120} INFO - >>El tiempo total de ejecucion del script [extract] es:     0.011081695556640625 Segundos
[2022-11-12T13:47:26.459+0000] {logging_mixin.py:120} INFO - [T]RANSFORM DATA
[2022-11-12T13:47:26.462+0000] {logging_mixin.py:120} INFO - Error mientras extracción de datos: (psycopg2.OperationalError) connection to server at "localhost" (127.0.0.1), port 5438 failed: Connection refused
	Is the server running on that host and accepting TCP/IP connections?
connection to server at "localhost" (::1), port 5438 failed: Cannot assign requested address
	Is the server running on that host and accepting TCP/IP connections?

(Background on this error at: https://sqlalche.me/e/14/e3q8)
[2022-11-12T13:47:26.465+0000] {logging_mixin.py:120} INFO - [L]OAD DATA 
[2022-11-12T13:47:26.467+0000] {logging_mixin.py:120} INFO - Error mientras extracción de datos: (psycopg2.OperationalError) connection to server at "localhost" (127.0.0.1), port 5438 failed: Connection refused
	Is the server running on that host and accepting TCP/IP connections?
connection to server at "localhost" (::1), port 5438 failed: Cannot assign requested address
	Is the server running on that host and accepting TCP/IP connections?

(Background on this error at: https://sqlalche.me/e/14/e3q8)
[2022-11-12T13:47:26.481+0000] {logging_mixin.py:120} INFO - [2022-11-12T13:47:26.477+0000] {dagbag.py:342} ERROR - Failed to import: /opt/airflow/dags/etl_testDef.py
Traceback (most recent call last):
  File "/home/airflow/.local/lib/python3.7/site-packages/airflow/models/dagbag.py", line 338, in parse
    loader.exec_module(new_module)
  File "<frozen importlib._bootstrap_external>", line 728, in exec_module
  File "<frozen importlib._bootstrap>", line 219, in _call_with_frames_removed
  File "/opt/airflow/dags/etl_testDef.py", line 37, in <module>
    python_callable=extract
  File "/home/airflow/.local/lib/python3.7/site-packages/airflow/models/baseoperator.py", line 408, in apply_defaults
    result = func(self, **kwargs, default_args=default_args)
  File "/home/airflow/.local/lib/python3.7/site-packages/airflow/operators/python.py", line 162, in __init__
    raise AirflowException('`python_callable` param must be callable')
airflow.exceptions.AirflowException: `python_callable` param must be callable
[2022-11-12T13:47:26.483+0000] {processor.py:768} WARNING - No viable dags retrieved from /opt/airflow/dags/etl_testDef.py
[2022-11-12T13:47:26.515+0000] {processor.py:176} INFO - Processing /opt/airflow/dags/etl_testDef.py took 0.674 seconds
