[2022-11-12T13:44:49.915+0000] {processor.py:154} INFO - Started process (PID=417) to work on /opt/airflow/dags/etl_testDef copy.py
[2022-11-12T13:44:49.920+0000] {processor.py:756} INFO - Processing file /opt/airflow/dags/etl_testDef copy.py for tasks to queue
[2022-11-12T13:44:49.926+0000] {logging_mixin.py:120} INFO - [2022-11-12T13:44:49.925+0000] {dagbag.py:537} INFO - Filling up the DagBag from /opt/airflow/dags/etl_testDef copy.py
[2022-11-12T13:44:50.465+0000] {logging_mixin.py:120} INFO - Grupo 99 ....>> runing ETL
[2022-11-12T13:44:50.469+0000] {logging_mixin.py:120} INFO - [E]XTRACT DATA
[2022-11-12T13:44:50.471+0000] {logging_mixin.py:120} INFO -   begin Extract >> PAYMENTS
[2022-11-12T13:44:50.473+0000] {logging_mixin.py:120} INFO - Error mientras extracci贸n de datos: [Errno 2] No such file or directory: '/Users/napo/Documents/proyecto/Big Data/BigData/data/payments'
[2022-11-12T13:44:50.475+0000] {logging_mixin.py:120} INFO -   >>end Extract PAYMENTS..
[2022-11-12T13:44:50.477+0000] {logging_mixin.py:120} INFO -   begin Extract >> CHARGEBACKS
[2022-11-12T13:44:50.479+0000] {logging_mixin.py:120} INFO - Error mientras extracci贸n de datos: [Errno 2] No such file or directory: '/Users/napo/Documents/proyecto/Big Data/BigData/data/chargebacks'
[2022-11-12T13:44:50.483+0000] {logging_mixin.py:120} INFO -   >>end Extract CHARGEBACKS..
[2022-11-12T13:44:50.485+0000] {logging_mixin.py:120} INFO - [end] - EXTRACT-DATA
[2022-11-12T13:44:50.487+0000] {logging_mixin.py:120} INFO - >>El tiempo total de ejecucion del script [extract] es:     0.02094554901123047 Segundos
[2022-11-12T13:44:50.491+0000] {logging_mixin.py:120} INFO - [T]RANSFORM DATA
[2022-11-12T13:44:50.500+0000] {logging_mixin.py:120} INFO - Error mientras extracci贸n de datos: (psycopg2.OperationalError) connection to server at "localhost" (127.0.0.1), port 5438 failed: Connection refused
	Is the server running on that host and accepting TCP/IP connections?
connection to server at "localhost" (::1), port 5438 failed: Cannot assign requested address
	Is the server running on that host and accepting TCP/IP connections?

(Background on this error at: https://sqlalche.me/e/14/e3q8)
[2022-11-12T13:44:50.506+0000] {logging_mixin.py:120} INFO - [L]OAD DATA 
[2022-11-12T13:44:50.512+0000] {logging_mixin.py:120} INFO - Error mientras extracci贸n de datos: (psycopg2.OperationalError) connection to server at "localhost" (127.0.0.1), port 5438 failed: Connection refused
	Is the server running on that host and accepting TCP/IP connections?
connection to server at "localhost" (::1), port 5438 failed: Cannot assign requested address
	Is the server running on that host and accepting TCP/IP connections?

(Background on this error at: https://sqlalche.me/e/14/e3q8)
[2022-11-12T13:44:50.530+0000] {logging_mixin.py:120} INFO - [2022-11-12T13:44:50.526+0000] {dagbag.py:342} ERROR - Failed to import: /opt/airflow/dags/etl_testDef copy.py
Traceback (most recent call last):
  File "/home/airflow/.local/lib/python3.7/site-packages/airflow/models/dagbag.py", line 338, in parse
    loader.exec_module(new_module)
  File "<frozen importlib._bootstrap_external>", line 728, in exec_module
  File "<frozen importlib._bootstrap>", line 219, in _call_with_frames_removed
  File "/opt/airflow/dags/etl_testDef copy.py", line 37, in <module>
    python_callable=extract
  File "/home/airflow/.local/lib/python3.7/site-packages/airflow/models/baseoperator.py", line 408, in apply_defaults
    result = func(self, **kwargs, default_args=default_args)
  File "/home/airflow/.local/lib/python3.7/site-packages/airflow/operators/python.py", line 162, in __init__
    raise AirflowException('`python_callable` param must be callable')
airflow.exceptions.AirflowException: `python_callable` param must be callable
[2022-11-12T13:44:50.537+0000] {processor.py:768} WARNING - No viable dags retrieved from /opt/airflow/dags/etl_testDef copy.py
[2022-11-12T13:44:50.657+0000] {processor.py:176} INFO - Processing /opt/airflow/dags/etl_testDef copy.py took 0.755 seconds
